WARNING:discord.gateway:Can't keep up, shard ID None websocket is 16.3s behind.
ERROR:discord.client:Attempting a reconnect in 1.71s
Traceback (most recent call last):
  File "C:\Users\trexx\AppData\Local\Programs\Python\Python39\lib\site-packages\discord\gateway.py", line 305, in from_client
    gateway = gateway or await client.http.get_gateway()
  File "C:\Users\trexx\AppData\Local\Programs\Python\Python39\lib\site-packages\discord\http.py", line 967, in get_gateway
    data = await self.request(Route('GET', '/gateway'))
  File "C:\Users\trexx\AppData\Local\Programs\Python\Python39\lib\site-packages\discord\http.py", line 192, in request
    async with self.__session.request(method, url, **kwargs) as r:
  File "C:\Users\trexx\AppData\Local\Programs\Python\Python39\lib\site-packages\aiohttp\client.py", line 1117, in __aenter__
    self._resp = await self._coro
  File "C:\Users\trexx\AppData\Local\Programs\Python\Python39\lib\site-packages\aiohttp\client.py", line 520, in _request
    conn = await self._connector.connect(
  File "C:\Users\trexx\AppData\Local\Programs\Python\Python39\lib\site-packages\aiohttp\connector.py", line 535, in connect
    proto = await self._create_connection(req, traces, timeout)
  File "C:\Users\trexx\AppData\Local\Programs\Python\Python39\lib\site-packages\aiohttp\connector.py", line 892, in _create_connection
    _, proto = await self._create_direct_connection(req, traces, timeout)
  File "C:\Users\trexx\AppData\Local\Programs\Python\Python39\lib\site-packages\aiohttp\connector.py", line 1020, in _create_direct_connection
    transp, proto = await self._wrap_create_connection(
  File "C:\Users\trexx\AppData\Local\Programs\Python\Python39\lib\site-packages\aiohttp\connector.py", line 969, in _wrap_create_connection
    return await self._loop.create_connection(*args, **kwargs)  # type: ignore  # noqa
  File "C:\Users\trexx\AppData\Local\Programs\Python\Python39\lib\asyncio\base_events.py", line 1081, in create_connection
    transport, protocol = await self._create_connection_transport(
  File "C:\Users\trexx\AppData\Local\Programs\Python\Python39\lib\asyncio\base_events.py", line 1111, in _create_connection_transport
    await waiter
asyncio.exceptions.CancelledError

During handling of the above exception, another exception occurred:

Traceback (most recent call last):
  File "C:\Users\trexx\AppData\Local\Programs\Python\Python39\lib\asyncio\tasks.py", line 492, in wait_for
    fut.result()
asyncio.exceptions.CancelledError

The above exception was the direct cause of the following exception:

Traceback (most recent call last):
  File "C:\Users\trexx\AppData\Local\Programs\Python\Python39\lib\site-packages\discord\client.py", line 563, in connect
    self.ws = await asyncio.wait_for(coro, timeout=60.0)
  File "C:\Users\trexx\AppData\Local\Programs\Python\Python39\lib\asyncio\tasks.py", line 494, in wait_for
    raise exceptions.TimeoutError() from exc
asyncio.exceptions.TimeoutError
ERROR:discord.client:Attempting a reconnect in 2.40s
Traceback (most recent call last):
  File "C:\Users\trexx\AppData\Local\Programs\Python\Python39\lib\site-packages\discord\gateway.py", line 305, in from_client
    gateway = gateway or await client.http.get_gateway()
  File "C:\Users\trexx\AppData\Local\Programs\Python\Python39\lib\site-packages\discord\http.py", line 967, in get_gateway
    data = await self.request(Route('GET', '/gateway'))
  File "C:\Users\trexx\AppData\Local\Programs\Python\Python39\lib\site-packages\discord\http.py", line 192, in request
    async with self.__session.request(method, url, **kwargs) as r:
  File "C:\Users\trexx\AppData\Local\Programs\Python\Python39\lib\site-packages\aiohttp\client.py", line 1117, in __aenter__
    self._resp = await self._coro
  File "C:\Users\trexx\AppData\Local\Programs\Python\Python39\lib\site-packages\aiohttp\client.py", line 520, in _request
    conn = await self._connector.connect(
  File "C:\Users\trexx\AppData\Local\Programs\Python\Python39\lib\site-packages\aiohttp\connector.py", line 535, in connect
    proto = await self._create_connection(req, traces, timeout)
  File "C:\Users\trexx\AppData\Local\Programs\Python\Python39\lib\site-packages\aiohttp\connector.py", line 892, in _create_connection
    _, proto = await self._create_direct_connection(req, traces, timeout)
  File "C:\Users\trexx\AppData\Local\Programs\Python\Python39\lib\site-packages\aiohttp\connector.py", line 1020, in _create_direct_connection
    transp, proto = await self._wrap_create_connection(
  File "C:\Users\trexx\AppData\Local\Programs\Python\Python39\lib\site-packages\aiohttp\connector.py", line 969, in _wrap_create_connection
    return await self._loop.create_connection(*args, **kwargs)  # type: ignore  # noqa
  File "C:\Users\trexx\AppData\Local\Programs\Python\Python39\lib\asyncio\base_events.py", line 1081, in create_connection
    transport, protocol = await self._create_connection_transport(
  File "C:\Users\trexx\AppData\Local\Programs\Python\Python39\lib\asyncio\base_events.py", line 1111, in _create_connection_transport
    await waiter
asyncio.exceptions.CancelledError

During handling of the above exception, another exception occurred:

Traceback (most recent call last):
  File "C:\Users\trexx\AppData\Local\Programs\Python\Python39\lib\asyncio\tasks.py", line 492, in wait_for
    fut.result()
asyncio.exceptions.CancelledError

The above exception was the direct cause of the following exception:

Traceback (most recent call last):
  File "C:\Users\trexx\AppData\Local\Programs\Python\Python39\lib\site-packages\discord\client.py", line 563, in connect
    self.ws = await asyncio.wait_for(coro, timeout=60.0)
  File "C:\Users\trexx\AppData\Local\Programs\Python\Python39\lib\asyncio\tasks.py", line 494, in wait_for
    raise exceptions.TimeoutError() from exc
asyncio.exceptions.TimeoutError
WARNING:discord.gateway:Can't keep up, shard ID None websocket is 12.3s behind.
WARNING:discord.gateway:Can't keep up, shard ID None websocket is 14.0s behind.
WARNING:discord.gateway:Can't keep up, shard ID None websocket is 11.4s behind.
ERROR:discord.client:Attempting a reconnect in 0.48s
Traceback (most recent call last):
  File "C:\Users\trexx\AppData\Local\Programs\Python\Python39\lib\site-packages\aiohttp\connector.py", line 999, in _create_direct_connection
    hosts = await asyncio.shield(host_resolved)
  File "C:\Users\trexx\AppData\Local\Programs\Python\Python39\lib\site-packages\aiohttp\connector.py", line 865, in _resolve_host
    addrs = await self._resolver.resolve(host, port, family=self._family)
  File "C:\Users\trexx\AppData\Local\Programs\Python\Python39\lib\site-packages\aiohttp\resolver.py", line 31, in resolve
    infos = await self._loop.getaddrinfo(
  File "C:\Users\trexx\AppData\Local\Programs\Python\Python39\lib\asyncio\base_events.py", line 856, in getaddrinfo
    return await self.run_in_executor(
  File "C:\Users\trexx\AppData\Local\Programs\Python\Python39\lib\concurrent\futures\thread.py", line 52, in run
    result = self.fn(*self.args, **self.kwargs)
  File "C:\Users\trexx\AppData\Local\Programs\Python\Python39\lib\socket.py", line 953, in getaddrinfo
    for res in _socket.getaddrinfo(host, port, family, type, proto, flags):
socket.gaierror: [Errno 11004] getaddrinfo failed

The above exception was the direct cause of the following exception:

Traceback (most recent call last):
  File "C:\Users\trexx\AppData\Local\Programs\Python\Python39\lib\site-packages\discord\client.py", line 563, in connect
    self.ws = await asyncio.wait_for(coro, timeout=60.0)
  File "C:\Users\trexx\AppData\Local\Programs\Python\Python39\lib\asyncio\tasks.py", line 481, in wait_for
    return fut.result()
  File "C:\Users\trexx\AppData\Local\Programs\Python\Python39\lib\site-packages\discord\gateway.py", line 305, in from_client
    gateway = gateway or await client.http.get_gateway()
  File "C:\Users\trexx\AppData\Local\Programs\Python\Python39\lib\site-packages\discord\http.py", line 967, in get_gateway
    data = await self.request(Route('GET', '/gateway'))
  File "C:\Users\trexx\AppData\Local\Programs\Python\Python39\lib\site-packages\discord\http.py", line 192, in request
    async with self.__session.request(method, url, **kwargs) as r:
  File "C:\Users\trexx\AppData\Local\Programs\Python\Python39\lib\site-packages\aiohttp\client.py", line 1117, in __aenter__
    self._resp = await self._coro
  File "C:\Users\trexx\AppData\Local\Programs\Python\Python39\lib\site-packages\aiohttp\client.py", line 520, in _request
    conn = await self._connector.connect(
  File "C:\Users\trexx\AppData\Local\Programs\Python\Python39\lib\site-packages\aiohttp\connector.py", line 535, in connect
    proto = await self._create_connection(req, traces, timeout)
  File "C:\Users\trexx\AppData\Local\Programs\Python\Python39\lib\site-packages\aiohttp\connector.py", line 892, in _create_connection
    _, proto = await self._create_direct_connection(req, traces, timeout)
  File "C:\Users\trexx\AppData\Local\Programs\Python\Python39\lib\site-packages\aiohttp\connector.py", line 1011, in _create_direct_connection
    raise ClientConnectorError(req.connection_key, exc) from exc
aiohttp.client_exceptions.ClientConnectorError: Cannot connect to host discord.com:443 ssl:default [getaddrinfo failed]
ERROR:discord.client:Attempting a reconnect in 2.35s
Traceback (most recent call last):
  File "C:\Users\trexx\AppData\Local\Programs\Python\Python39\lib\site-packages\aiohttp\connector.py", line 999, in _create_direct_connection
    hosts = await asyncio.shield(host_resolved)
  File "C:\Users\trexx\AppData\Local\Programs\Python\Python39\lib\site-packages\aiohttp\connector.py", line 865, in _resolve_host
    addrs = await self._resolver.resolve(host, port, family=self._family)
  File "C:\Users\trexx\AppData\Local\Programs\Python\Python39\lib\site-packages\aiohttp\resolver.py", line 31, in resolve
    infos = await self._loop.getaddrinfo(
  File "C:\Users\trexx\AppData\Local\Programs\Python\Python39\lib\asyncio\base_events.py", line 856, in getaddrinfo
    return await self.run_in_executor(
  File "C:\Users\trexx\AppData\Local\Programs\Python\Python39\lib\concurrent\futures\thread.py", line 52, in run
    result = self.fn(*self.args, **self.kwargs)
  File "C:\Users\trexx\AppData\Local\Programs\Python\Python39\lib\socket.py", line 953, in getaddrinfo
    for res in _socket.getaddrinfo(host, port, family, type, proto, flags):
socket.gaierror: [Errno 11004] getaddrinfo failed

The above exception was the direct cause of the following exception:

Traceback (most recent call last):
  File "C:\Users\trexx\AppData\Local\Programs\Python\Python39\lib\site-packages\discord\client.py", line 563, in connect
    self.ws = await asyncio.wait_for(coro, timeout=60.0)
  File "C:\Users\trexx\AppData\Local\Programs\Python\Python39\lib\asyncio\tasks.py", line 481, in wait_for
    return fut.result()
  File "C:\Users\trexx\AppData\Local\Programs\Python\Python39\lib\site-packages\discord\gateway.py", line 305, in from_client
    gateway = gateway or await client.http.get_gateway()
  File "C:\Users\trexx\AppData\Local\Programs\Python\Python39\lib\site-packages\discord\http.py", line 967, in get_gateway
    data = await self.request(Route('GET', '/gateway'))
  File "C:\Users\trexx\AppData\Local\Programs\Python\Python39\lib\site-packages\discord\http.py", line 192, in request
    async with self.__session.request(method, url, **kwargs) as r:
  File "C:\Users\trexx\AppData\Local\Programs\Python\Python39\lib\site-packages\aiohttp\client.py", line 1117, in __aenter__
    self._resp = await self._coro
  File "C:\Users\trexx\AppData\Local\Programs\Python\Python39\lib\site-packages\aiohttp\client.py", line 520, in _request
    conn = await self._connector.connect(
  File "C:\Users\trexx\AppData\Local\Programs\Python\Python39\lib\site-packages\aiohttp\connector.py", line 535, in connect
    proto = await self._create_connection(req, traces, timeout)
  File "C:\Users\trexx\AppData\Local\Programs\Python\Python39\lib\site-packages\aiohttp\connector.py", line 892, in _create_connection
    _, proto = await self._create_direct_connection(req, traces, timeout)
  File "C:\Users\trexx\AppData\Local\Programs\Python\Python39\lib\site-packages\aiohttp\connector.py", line 1011, in _create_direct_connection
    raise ClientConnectorError(req.connection_key, exc) from exc
aiohttp.client_exceptions.ClientConnectorError: Cannot connect to host discord.com:443 ssl:default [getaddrinfo failed]
WARNING:discord.http:We are being rate limited. Retrying in 0.12 seconds. Handled under the bucket "859145748988559365:None:/channels/{channel_id}/messages/{message_id}/reactions/{emoji}/@me"
WARNING:discord.http:We are being rate limited. Retrying in 0.15 seconds. Handled under the bucket "859145748988559365:None:/channels/{channel_id}/messages/{message_id}/reactions/{emoji}/@me"
WARNING:discord.http:We are being rate limited. Retrying in 0.10 seconds. Handled under the bucket "859145748988559365:None:/channels/{channel_id}/messages/{message_id}/reactions/{emoji}/@me"
WARNING:discord.http:We are being rate limited. Retrying in 0.15 seconds. Handled under the bucket "859145748988559365:None:/channels/{channel_id}/messages/{message_id}/reactions/{emoji}/@me"
WARNING:discord.http:We are being rate limited. Retrying in 0.14 seconds. Handled under the bucket "859145777141121045:None:/channels/{channel_id}/messages/{message_id}/reactions/{emoji}/@me"
WARNING:discord.http:We are being rate limited. Retrying in 0.08 seconds. Handled under the bucket "859145777141121045:None:/channels/{channel_id}/messages/{message_id}/reactions/{emoji}/@me"
WARNING:discord.http:We are being rate limited. Retrying in 0.13 seconds. Handled under the bucket "859145777141121045:None:/channels/{channel_id}/messages/{message_id}/reactions/{emoji}/@me"
WARNING:discord.http:We are being rate limited. Retrying in 0.13 seconds. Handled under the bucket "859145777141121045:None:/channels/{channel_id}/messages/{message_id}/reactions/{emoji}/@me"
WARNING:discord.http:We are being rate limited. Retrying in 0.12 seconds. Handled under the bucket "859145777141121045:None:/channels/{channel_id}/messages/{message_id}/reactions/{emoji}/@me"
WARNING:discord.http:We are being rate limited. Retrying in 0.02 seconds. Handled under the bucket "859145777141121045:None:/channels/{channel_id}/messages/{message_id}/reactions/{emoji}/@me"
WARNING:discord.http:We are being rate limited. Retrying in 0.15 seconds. Handled under the bucket "859145777141121045:None:/channels/{channel_id}/messages/{message_id}/reactions/{emoji}/@me"
WARNING:discord.http:We are being rate limited. Retrying in 0.16 seconds. Handled under the bucket "859145777141121045:None:/channels/{channel_id}/messages/{message_id}/reactions/{emoji}/@me"
WARNING:discord.http:We are being rate limited. Retrying in 0.15 seconds. Handled under the bucket "859145777141121045:None:/channels/{channel_id}/messages/{message_id}/reactions/{emoji}/@me"
WARNING:discord.http:We are being rate limited. Retrying in 0.10 seconds. Handled under the bucket "859145777141121045:None:/channels/{channel_id}/messages/{message_id}/reactions/{emoji}/@me"
WARNING:discord.http:We are being rate limited. Retrying in 0.15 seconds. Handled under the bucket "859145777141121045:None:/channels/{channel_id}/messages/{message_id}/reactions/{emoji}/@me"
WARNING:discord.http:We are being rate limited. Retrying in 0.11 seconds. Handled under the bucket "859145777141121045:None:/channels/{channel_id}/messages/{message_id}/reactions/{emoji}/@me"
WARNING:discord.http:We are being rate limited. Retrying in 0.15 seconds. Handled under the bucket "859145777141121045:None:/channels/{channel_id}/messages/{message_id}/reactions/{emoji}/@me"
WARNING:discord.http:We are being rate limited. Retrying in 0.13 seconds. Handled under the bucket "859145777141121045:None:/channels/{channel_id}/messages/{message_id}/reactions/{emoji}/@me"
WARNING:discord.http:We are being rate limited. Retrying in 0.15 seconds. Handled under the bucket "859145748988559365:None:/channels/{channel_id}/messages/{message_id}/reactions/{emoji}/@me"
WARNING:discord.http:We are being rate limited. Retrying in 0.12 seconds. Handled under the bucket "859145748988559365:None:/channels/{channel_id}/messages/{message_id}/reactions/{emoji}/@me"
WARNING:discord.http:We are being rate limited. Retrying in 0.01 seconds. Handled under the bucket "859145748988559365:None:/channels/{channel_id}/messages/{message_id}/reactions/{emoji}/@me"
WARNING:discord.http:We are being rate limited. Retrying in 0.05 seconds. Handled under the bucket "859145748988559365:None:/channels/{channel_id}/messages/{message_id}/reactions/{emoji}/@me"
WARNING:discord.http:We are being rate limited. Retrying in 0.04 seconds. Handled under the bucket "859145748988559365:None:/channels/{channel_id}/messages/{message_id}/reactions/{emoji}/@me"
WARNING:discord.http:We are being rate limited. Retrying in 0.05 seconds. Handled under the bucket "859145748988559365:None:/channels/{channel_id}/messages/{message_id}/reactions/{emoji}/@me"
WARNING:discord.http:We are being rate limited. Retrying in 0.13 seconds. Handled under the bucket "859145748988559365:None:/channels/{channel_id}/messages/{message_id}/reactions/{emoji}/@me"
CRITICAL:imdbpy:IMDbDataAccessError exception raised; args: ({'errcode': None, 'errmsg': 'None', 'url': 'https://www.imdb.com/title/tt0087538/episodes', 'proxy': '', 'exception type': 'IOError', 'original exception': <HTTPError 404: ''>},); kwds: {}
Traceback (most recent call last):
  File "C:\Users\trexx\AppData\Local\Programs\Python\Python39\lib\site-packages\imdb\parser\http\__init__.py", line 220, in retrieve_unicode
    response = uopener.open(url)
  File "C:\Users\trexx\AppData\Local\Programs\Python\Python39\lib\urllib\request.py", line 523, in open
    response = meth(req, response)
  File "C:\Users\trexx\AppData\Local\Programs\Python\Python39\lib\urllib\request.py", line 632, in http_response
    response = self.parent.error(
  File "C:\Users\trexx\AppData\Local\Programs\Python\Python39\lib\urllib\request.py", line 561, in error
    return self._call_chain(*args)
  File "C:\Users\trexx\AppData\Local\Programs\Python\Python39\lib\urllib\request.py", line 494, in _call_chain
    result = func(*args)
  File "C:\Users\trexx\AppData\Local\Programs\Python\Python39\lib\urllib\request.py", line 641, in http_error_default
    raise HTTPError(req.full_url, code, msg, hdrs, fp)
urllib.error.HTTPError: HTTP Error 404: 
WARNING:discord.http:We are being rate limited. Retrying in 0.15 seconds. Handled under the bucket "859145748988559365:None:/channels/{channel_id}/messages/{message_id}/reactions/{emoji}/@me"
WARNING:discord.http:We are being rate limited. Retrying in 0.13 seconds. Handled under the bucket "859145748988559365:None:/channels/{channel_id}/messages/{message_id}/reactions/{emoji}/@me"
WARNING:discord.http:We are being rate limited. Retrying in 0.11 seconds. Handled under the bucket "859145748988559365:None:/channels/{channel_id}/messages/{message_id}/reactions/{emoji}/@me"
WARNING:discord.http:We are being rate limited. Retrying in 0.12 seconds. Handled under the bucket "859145748988559365:None:/channels/{channel_id}/messages/{message_id}/reactions/{emoji}/@me"
WARNING:discord.http:We are being rate limited. Retrying in 0.14 seconds. Handled under the bucket "859145748988559365:None:/channels/{channel_id}/messages/{message_id}/reactions/{emoji}/@me"
WARNING:discord.http:We are being rate limited. Retrying in 0.14 seconds. Handled under the bucket "859145748988559365:None:/channels/{channel_id}/messages/{message_id}/reactions/{emoji}/@me"
WARNING:discord.http:We are being rate limited. Retrying in 0.13 seconds. Handled under the bucket "859145748988559365:None:/channels/{channel_id}/messages/{message_id}/reactions/{emoji}/@me"
WARNING:discord.http:We are being rate limited. Retrying in 0.11 seconds. Handled under the bucket "859145748988559365:None:/channels/{channel_id}/messages/{message_id}/reactions/{emoji}/@me"
WARNING:discord.http:We are being rate limited. Retrying in 0.15 seconds. Handled under the bucket "859145748988559365:None:/channels/{channel_id}/messages/{message_id}/reactions/{emoji}/@me"
WARNING:discord.http:We are being rate limited. Retrying in 0.14 seconds. Handled under the bucket "859145748988559365:None:/channels/{channel_id}/messages/{message_id}/reactions/{emoji}/@me"
WARNING:discord.http:We are being rate limited. Retrying in 0.15 seconds. Handled under the bucket "859145748988559365:None:/channels/{channel_id}/messages/{message_id}/reactions/{emoji}/@me"
WARNING:discord.http:We are being rate limited. Retrying in 0.14 seconds. Handled under the bucket "859145748988559365:None:/channels/{channel_id}/messages/{message_id}/reactions/{emoji}/@me"
WARNING:discord.gateway:Shard ID None heartbeat blocked for more than 10 seconds.
Loop thread traceback (most recent call last):
  File "c:\Users\trexx\Documents\PYTHON CODE LOL\SCP-16-Tsundere-Discord-Bot\SCP\SCP-16-Tsundere.py", line 1923, in <module>
    client.run("ODIyMjY1NjE0MjQ0NTExNzU0.YFPwhw.cOH2DLXY1c06IsdDl6_WVuG2OLI")
  File "C:\Users\trexx\AppData\Local\Programs\Python\Python39\lib\site-packages\discord\client.py", line 713, in run
    loop.run_forever()
  File "C:\Users\trexx\AppData\Local\Programs\Python\Python39\lib\asyncio\windows_events.py", line 316, in run_forever
    super().run_forever()
  File "C:\Users\trexx\AppData\Local\Programs\Python\Python39\lib\asyncio\base_events.py", line 596, in run_forever
    self._run_once()
  File "C:\Users\trexx\AppData\Local\Programs\Python\Python39\lib\asyncio\base_events.py", line 1890, in _run_once
    handle._run()
  File "C:\Users\trexx\AppData\Local\Programs\Python\Python39\lib\asyncio\events.py", line 80, in _run
    self._context.run(self._callback, *self._args)
  File "C:\Users\trexx\AppData\Local\Programs\Python\Python39\lib\site-packages\discord\client.py", line 343, in _run_event
    await coro(*args, **kwargs)
  File "c:\Users\trexx\Documents\PYTHON CODE LOL\SCP-16-Tsundere-Discord-Bot\SCP\currencysys.py", line 168, in on_message
    dbcheck(ctx.author)
  File "c:\Users\trexx\Documents\PYTHON CODE LOL\SCP-16-Tsundere-Discord-Bot\SCP\currencysys.py", line 162, in dbcheck
    value = mulah.find_one({"id":ctx.author.id},{x["name"]})[x["name"]]
  File "C:\Users\trexx\AppData\Local\Programs\Python\Python39\lib\site-packages\pymongo\collection.py", line 1319, in find_one
    for result in cursor.limit(-1):
  File "C:\Users\trexx\AppData\Local\Programs\Python\Python39\lib\site-packages\pymongo\cursor.py", line 1207, in next
    if len(self.__data) or self._refresh():
  File "C:\Users\trexx\AppData\Local\Programs\Python\Python39\lib\site-packages\pymongo\cursor.py", line 1124, in _refresh
    self.__send_message(q)
  File "C:\Users\trexx\AppData\Local\Programs\Python\Python39\lib\site-packages\pymongo\cursor.py", line 999, in __send_message
    response = client._run_operation_with_response(
  File "C:\Users\trexx\AppData\Local\Programs\Python\Python39\lib\site-packages\pymongo\mongo_client.py", line 1368, in _run_operation_with_response
    return self._retryable_read(
  File "C:\Users\trexx\AppData\Local\Programs\Python\Python39\lib\site-packages\pymongo\mongo_client.py", line 1460, in _retryable_read
    server = self._select_server(
  File "C:\Users\trexx\AppData\Local\Programs\Python\Python39\lib\site-packages\pymongo\mongo_client.py", line 1278, in _select_server
    server = topology.select_server(server_selector)
  File "C:\Users\trexx\AppData\Local\Programs\Python\Python39\lib\site-packages\pymongo\topology.py", line 241, in select_server
    return random.choice(self.select_servers(selector,
  File "C:\Users\trexx\AppData\Local\Programs\Python\Python39\lib\site-packages\pymongo\topology.py", line 199, in select_servers
    server_descriptions = self._select_servers_loop(
  File "C:\Users\trexx\AppData\Local\Programs\Python\Python39\lib\site-packages\pymongo\topology.py", line 226, in _select_servers_loop
    self._condition.wait(common.MIN_HEARTBEAT_INTERVAL)
  File "C:\Users\trexx\AppData\Local\Programs\Python\Python39\lib\threading.py", line 316, in wait
    gotit = waiter.acquire(True, timeout)

WARNING:discord.gateway:Shard ID None heartbeat blocked for more than 20 seconds.
Loop thread traceback (most recent call last):
  File "c:\Users\trexx\Documents\PYTHON CODE LOL\SCP-16-Tsundere-Discord-Bot\SCP\SCP-16-Tsundere.py", line 1923, in <module>
    client.run("ODIyMjY1NjE0MjQ0NTExNzU0.YFPwhw.cOH2DLXY1c06IsdDl6_WVuG2OLI")
  File "C:\Users\trexx\AppData\Local\Programs\Python\Python39\lib\site-packages\discord\client.py", line 713, in run
    loop.run_forever()
  File "C:\Users\trexx\AppData\Local\Programs\Python\Python39\lib\asyncio\windows_events.py", line 316, in run_forever
    super().run_forever()
  File "C:\Users\trexx\AppData\Local\Programs\Python\Python39\lib\asyncio\base_events.py", line 596, in run_forever
    self._run_once()
  File "C:\Users\trexx\AppData\Local\Programs\Python\Python39\lib\asyncio\base_events.py", line 1890, in _run_once
    handle._run()
  File "C:\Users\trexx\AppData\Local\Programs\Python\Python39\lib\asyncio\events.py", line 80, in _run
    self._context.run(self._callback, *self._args)
  File "C:\Users\trexx\AppData\Local\Programs\Python\Python39\lib\site-packages\discord\client.py", line 343, in _run_event
    await coro(*args, **kwargs)
  File "c:\Users\trexx\Documents\PYTHON CODE LOL\SCP-16-Tsundere-Discord-Bot\SCP\currencysys.py", line 168, in on_message
    dbcheck(ctx.author)
  File "c:\Users\trexx\Documents\PYTHON CODE LOL\SCP-16-Tsundere-Discord-Bot\SCP\currencysys.py", line 162, in dbcheck
    value = mulah.find_one({"id":ctx.author.id},{x["name"]})[x["name"]]
  File "C:\Users\trexx\AppData\Local\Programs\Python\Python39\lib\site-packages\pymongo\collection.py", line 1319, in find_one
    for result in cursor.limit(-1):
  File "C:\Users\trexx\AppData\Local\Programs\Python\Python39\lib\site-packages\pymongo\cursor.py", line 1207, in next
    if len(self.__data) or self._refresh():
  File "C:\Users\trexx\AppData\Local\Programs\Python\Python39\lib\site-packages\pymongo\cursor.py", line 1124, in _refresh
    self.__send_message(q)
  File "C:\Users\trexx\AppData\Local\Programs\Python\Python39\lib\site-packages\pymongo\cursor.py", line 999, in __send_message
    response = client._run_operation_with_response(
  File "C:\Users\trexx\AppData\Local\Programs\Python\Python39\lib\site-packages\pymongo\mongo_client.py", line 1368, in _run_operation_with_response
    return self._retryable_read(
  File "C:\Users\trexx\AppData\Local\Programs\Python\Python39\lib\site-packages\pymongo\mongo_client.py", line 1460, in _retryable_read
    server = self._select_server(
  File "C:\Users\trexx\AppData\Local\Programs\Python\Python39\lib\site-packages\pymongo\mongo_client.py", line 1278, in _select_server
    server = topology.select_server(server_selector)
  File "C:\Users\trexx\AppData\Local\Programs\Python\Python39\lib\site-packages\pymongo\topology.py", line 241, in select_server
    return random.choice(self.select_servers(selector,
  File "C:\Users\trexx\AppData\Local\Programs\Python\Python39\lib\site-packages\pymongo\topology.py", line 199, in select_servers
    server_descriptions = self._select_servers_loop(
  File "C:\Users\trexx\AppData\Local\Programs\Python\Python39\lib\site-packages\pymongo\topology.py", line 226, in _select_servers_loop
    self._condition.wait(common.MIN_HEARTBEAT_INTERVAL)
  File "C:\Users\trexx\AppData\Local\Programs\Python\Python39\lib\threading.py", line 316, in wait
    gotit = waiter.acquire(True, timeout)

